2020-09-09 20:49:54,665 DEBUG Trying to acquire lock on file /Users/sean.ogormanibm.com/secondrescom/resilient-community-apps/.pyre/recently-used-local-configurations.lock
2020-09-09 20:49:54,666 DEBUG No existing file `/Users/sean.ogormanibm.com/secondrescom/resilient-community-apps/.pyre/recently-used-local-configurations.json`.
2020-09-09 20:49:54,671 INFO Constructing shared directory `/Users/sean.ogormanibm.com/secondrescom/resilient-community-apps/.pyre/rc-data-feed_53683`
2020-09-09 20:49:54,671 INFO Normalizing target ``
2020-09-09 20:49:54,687 ERROR Traceback (most recent call last):
  File "/Users/sean.ogormanibm.com/.pyenv/versions/3.6.9/envs/ssltest/lib/python3.6/site-packages/pyre_check/client/pyre.py", line 121, in run_pyre
    exit_code = command.run().exit_code()
  File "/Users/sean.ogormanibm.com/.pyenv/versions/3.6.9/envs/ssltest/lib/python3.6/site-packages/pyre_check/client/commands/command.py", line 609, in run
    self._run()
  File "/Users/sean.ogormanibm.com/.pyenv/versions/3.6.9/envs/ssltest/lib/python3.6/site-packages/pyre_check/client/commands/check.py", line 102, in _run
    self._analysis_directory.prepare()
  File "/Users/sean.ogormanibm.com/.pyenv/versions/3.6.9/envs/ssltest/lib/python3.6/site-packages/pyre_check/client/analysis_directory.py", line 276, in prepare
    self._resolve_source_directories()
  File "/Users/sean.ogormanibm.com/.pyenv/versions/3.6.9/envs/ssltest/lib/python3.6/site-packages/pyre_check/client/analysis_directory.py", line 250, in _resolve_source_directories
    new_source_directories = self._buck_builder.build(self._targets)
  File "/Users/sean.ogormanibm.com/.pyenv/versions/3.6.9/envs/ssltest/lib/python3.6/site-packages/pyre_check/client/buck.py", line 146, in build
    return generate_source_directories(targets)
  File "/Users/sean.ogormanibm.com/.pyenv/versions/3.6.9/envs/ssltest/lib/python3.6/site-packages/pyre_check/client/buck.py", line 354, in generate_source_directories
    targets_to_destinations = _normalize(original_targets)
  File "/Users/sean.ogormanibm.com/.pyenv/versions/3.6.9/envs/ssltest/lib/python3.6/site-packages/pyre_check/client/buck.py", line 208, in _normalize
    subprocess.check_output(command, stderr=subprocess.PIPE, timeout=600)
  File "/Users/sean.ogormanibm.com/.pyenv/versions/3.6.9/lib/python3.6/subprocess.py", line 356, in check_output
    **kwargs).stdout
  File "/Users/sean.ogormanibm.com/.pyenv/versions/3.6.9/lib/python3.6/subprocess.py", line 423, in run
    with Popen(*popenargs, **kwargs) as process:
  File "/Users/sean.ogormanibm.com/.pyenv/versions/3.6.9/lib/python3.6/subprocess.py", line 729, in __init__
    restore_signals, start_new_session)
  File "/Users/sean.ogormanibm.com/.pyenv/versions/3.6.9/lib/python3.6/subprocess.py", line 1364, in _execute_child
    raise child_exception_type(errno_num, err_msg, err_filename)
FileNotFoundError: [Errno 2] No such file or directory: 'buck': 'buck'


2020-09-09 20:49:54,688 DEBUG Could not clean up analysis directory: [Errno 2] No such file or directory: '/Users/sean.ogormanibm.com/secondrescom/resilient-community-apps/.pyre/rc-data-feed_53683'
2020-09-09 20:50:04,014 DEBUG Trying to acquire lock on file /Users/sean.ogormanibm.com/secondrescom/resilient-community-apps/.pyre/recently-used-local-configurations.lock
2020-09-09 20:50:04,018 INFO Constructing shared directory `/Users/sean.ogormanibm.com/secondrescom/resilient-community-apps/.pyre/rc-data-feed_53738`
2020-09-09 20:50:04,018 INFO Normalizing target ``
2020-09-09 20:50:04,025 ERROR Traceback (most recent call last):
  File "/Users/sean.ogormanibm.com/.pyenv/versions/3.6.9/envs/ssltest/lib/python3.6/site-packages/pyre_check/client/pyre.py", line 121, in run_pyre
    exit_code = command.run().exit_code()
  File "/Users/sean.ogormanibm.com/.pyenv/versions/3.6.9/envs/ssltest/lib/python3.6/site-packages/pyre_check/client/commands/command.py", line 609, in run
    self._run()
  File "/Users/sean.ogormanibm.com/.pyenv/versions/3.6.9/envs/ssltest/lib/python3.6/site-packages/pyre_check/client/commands/check.py", line 102, in _run
    self._analysis_directory.prepare()
  File "/Users/sean.ogormanibm.com/.pyenv/versions/3.6.9/envs/ssltest/lib/python3.6/site-packages/pyre_check/client/analysis_directory.py", line 276, in prepare
    self._resolve_source_directories()
  File "/Users/sean.ogormanibm.com/.pyenv/versions/3.6.9/envs/ssltest/lib/python3.6/site-packages/pyre_check/client/analysis_directory.py", line 250, in _resolve_source_directories
    new_source_directories = self._buck_builder.build(self._targets)
  File "/Users/sean.ogormanibm.com/.pyenv/versions/3.6.9/envs/ssltest/lib/python3.6/site-packages/pyre_check/client/buck.py", line 146, in build
    return generate_source_directories(targets)
  File "/Users/sean.ogormanibm.com/.pyenv/versions/3.6.9/envs/ssltest/lib/python3.6/site-packages/pyre_check/client/buck.py", line 354, in generate_source_directories
    targets_to_destinations = _normalize(original_targets)
  File "/Users/sean.ogormanibm.com/.pyenv/versions/3.6.9/envs/ssltest/lib/python3.6/site-packages/pyre_check/client/buck.py", line 208, in _normalize
    subprocess.check_output(command, stderr=subprocess.PIPE, timeout=600)
  File "/Users/sean.ogormanibm.com/.pyenv/versions/3.6.9/lib/python3.6/subprocess.py", line 356, in check_output
    **kwargs).stdout
  File "/Users/sean.ogormanibm.com/.pyenv/versions/3.6.9/lib/python3.6/subprocess.py", line 423, in run
    with Popen(*popenargs, **kwargs) as process:
  File "/Users/sean.ogormanibm.com/.pyenv/versions/3.6.9/lib/python3.6/subprocess.py", line 729, in __init__
    restore_signals, start_new_session)
  File "/Users/sean.ogormanibm.com/.pyenv/versions/3.6.9/lib/python3.6/subprocess.py", line 1364, in _execute_child
    raise child_exception_type(errno_num, err_msg, err_filename)
FileNotFoundError: [Errno 2] No such file or directory: 'buck': 'buck'


2020-09-09 20:50:04,026 DEBUG Could not clean up analysis directory: [Errno 2] No such file or directory: '/Users/sean.ogormanibm.com/secondrescom/resilient-community-apps/.pyre/rc-data-feed_53738'
